==68002== Memcheck, a memory error detector
==68002== Copyright (C) 2002-2024, and GNU GPL'd, by Julian Seward et al.
==68002== Using Valgrind-3.25.1 and LibVEX; rerun with -h for copyright info
==68002== Command: python3 symnmf.py 0 ddg ./tests/input_1.txt
==68002== 
==68002== 
==68002== HEAP SUMMARY:
==68002==     in use at exit: 1,973,325 bytes in 1,110 blocks
==68002==   total heap usage: 12,283 allocs, 11,173 frees, 15,756,632 bytes allocated
==68002== 
==68002== 520 bytes in 1 blocks are possibly lost in loss record 94 of 425
==68002==    at 0x4E3880F: malloc (vg_replace_malloc.c:446)
==68002==    by 0x414FEC7: _PyObject_GC_NewVar (in /usr/bin/python3.10)
==68002==    by 0x4174C84: ??? (in /usr/bin/python3.10)
==68002==    by 0x41989C0: ??? (in /usr/bin/python3.10)
==68002==    by 0x4180AC2: _PyObject_FastCallDictTstate (in /usr/bin/python3.10)
==68002==    by 0x4182A13: ??? (in /usr/bin/python3.10)
==68002==    by 0x41CB998: ??? (in /usr/bin/python3.10)
==68002==    by 0x418AE11: ??? (in /usr/bin/python3.10)
==68002==    by 0x41993CA: PyObject_Call (in /usr/bin/python3.10)
==68002==    by 0x417B9FB: _PyEval_EvalFrameDefault (in /usr/bin/python3.10)
==68002==    by 0x4180933: _PyObject_FastCallDictTstate (in /usr/bin/python3.10)
==68002==    by 0x41CB27C: ??? (in /usr/bin/python3.10)
==68002== 
==68002== 520 bytes in 1 blocks are possibly lost in loss record 95 of 425
==68002==    at 0x4E3880F: malloc (vg_replace_malloc.c:446)
==68002==    by 0x414FEC7: _PyObject_GC_NewVar (in /usr/bin/python3.10)
==68002==    by 0x4174C84: ??? (in /usr/bin/python3.10)
==68002==    by 0x4180903: _PyObject_FastCallDictTstate (in /usr/bin/python3.10)
==68002==    by 0x4194B03: ??? (in /usr/bin/python3.10)
==68002==    by 0x41816FB: _PyObject_MakeTpCall (in /usr/bin/python3.10)
==68002==    by 0x417AC46: _PyEval_EvalFrameDefault (in /usr/bin/python3.10)
==68002==    by 0x4259F55: ??? (in /usr/bin/python3.10)
==68002==    by 0x4259E25: PyEval_EvalCode (in /usr/bin/python3.10)
==68002==    by 0x425F4FC: ??? (in /usr/bin/python3.10)
==68002==    by 0x418B8C8: ??? (in /usr/bin/python3.10)
==68002==    by 0x417B9FB: _PyEval_EvalFrameDefault (in /usr/bin/python3.10)
==68002== 
==68002== 536 bytes in 1 blocks are possibly lost in loss record 98 of 425
==68002==    at 0x4E3880F: malloc (vg_replace_malloc.c:446)
==68002==    by 0x414FEC7: _PyObject_GC_NewVar (in /usr/bin/python3.10)
==68002==    by 0x4174C84: ??? (in /usr/bin/python3.10)
==68002==    by 0x4180903: _PyObject_FastCallDictTstate (in /usr/bin/python3.10)
==68002==    by 0x41CB27C: ??? (in /usr/bin/python3.10)
==68002==    by 0x41816A6: _PyObject_MakeTpCall (in /usr/bin/python3.10)
==68002==    by 0x417EC93: ??? (in /usr/bin/python3.10)
==68002==    by 0x417E82E: ??? (in /usr/bin/python3.10)
==68002==    by 0x417592E: _PyEval_EvalFrameDefault (in /usr/bin/python3.10)
==68002==    by 0x4259F55: ??? (in /usr/bin/python3.10)
==68002==    by 0x4259E25: PyEval_EvalCode (in /usr/bin/python3.10)
==68002==    by 0x425F4FC: ??? (in /usr/bin/python3.10)
==68002== 
==68002== 536 bytes in 1 blocks are possibly lost in loss record 99 of 425
==68002==    at 0x4E3880F: malloc (vg_replace_malloc.c:446)
==68002==    by 0x414F2AD: ??? (in /usr/bin/python3.10)
==68002==    by 0x4191BBC: PyObject_Realloc (in /usr/bin/python3.10)
==68002==    by 0x426163C: _PyObject_GC_Resize (in /usr/bin/python3.10)
==68002==    by 0x4174D97: ??? (in /usr/bin/python3.10)
==68002==    by 0x4180903: _PyObject_FastCallDictTstate (in /usr/bin/python3.10)
==68002==    by 0x41CB27C: ??? (in /usr/bin/python3.10)
==68002==    by 0x41816A6: _PyObject_MakeTpCall (in /usr/bin/python3.10)
==68002==    by 0x417EC93: ??? (in /usr/bin/python3.10)
==68002==    by 0x417E82E: ??? (in /usr/bin/python3.10)
==68002==    by 0x417592E: _PyEval_EvalFrameDefault (in /usr/bin/python3.10)
==68002==    by 0x4259F55: ??? (in /usr/bin/python3.10)
==68002== 
==68002== 568 bytes in 1 blocks are possibly lost in loss record 104 of 425
==68002==    at 0x4E3880F: malloc (vg_replace_malloc.c:446)
==68002==    by 0x414FEC7: _PyObject_GC_NewVar (in /usr/bin/python3.10)
==68002==    by 0x4174C84: ??? (in /usr/bin/python3.10)
==68002==    by 0x418B63D: _PyFunction_Vectorcall (in /usr/bin/python3.10)
==68002==    by 0x4175A73: _PyEval_EvalFrameDefault (in /usr/bin/python3.10)
==68002==    by 0x418B66B: _PyFunction_Vectorcall (in /usr/bin/python3.10)
==68002==    by 0x4175A73: _PyEval_EvalFrameDefault (in /usr/bin/python3.10)
==68002==    by 0x418B66B: _PyFunction_Vectorcall (in /usr/bin/python3.10)
==68002==    by 0x417592E: _PyEval_EvalFrameDefault (in /usr/bin/python3.10)
==68002==    by 0x418B66B: _PyFunction_Vectorcall (in /usr/bin/python3.10)
==68002==    by 0x417592E: _PyEval_EvalFrameDefault (in /usr/bin/python3.10)
==68002==    by 0x418B66B: _PyFunction_Vectorcall (in /usr/bin/python3.10)
==68002== 
==68002== 624 bytes in 1 blocks are possibly lost in loss record 192 of 425
==68002==    at 0x4E3880F: malloc (vg_replace_malloc.c:446)
==68002==    by 0x414FEC7: _PyObject_GC_NewVar (in /usr/bin/python3.10)
==68002==    by 0x4174C84: ??? (in /usr/bin/python3.10)
==68002==    by 0x419875F: ??? (in /usr/bin/python3.10)
==68002==    by 0x4176B42: _PyEval_EvalFrameDefault (in /usr/bin/python3.10)
==68002==    by 0x418B66B: _PyFunction_Vectorcall (in /usr/bin/python3.10)
==68002==    by 0x41809DC: _PyObject_FastCallDictTstate (in /usr/bin/python3.10)
==68002==    by 0x41958EB: _PyObject_Call_Prepend (in /usr/bin/python3.10)
==68002==    by 0x429CBA3: ??? (in /usr/bin/python3.10)
==68002==    by 0x418175A: _PyObject_MakeTpCall (in /usr/bin/python3.10)
==68002==    by 0x417B961: _PyEval_EvalFrameDefault (in /usr/bin/python3.10)
==68002==    by 0x4198790: ??? (in /usr/bin/python3.10)
==68002== 
==68002== 704 bytes in 1 blocks are possibly lost in loss record 196 of 425
==68002==    at 0x4E3880F: malloc (vg_replace_malloc.c:446)
==68002==    by 0x414FEC7: _PyObject_GC_NewVar (in /usr/bin/python3.10)
==68002==    by 0x4174C84: ??? (in /usr/bin/python3.10)
==68002==    by 0x4180903: _PyObject_FastCallDictTstate (in /usr/bin/python3.10)
==68002==    by 0x41CB27C: ??? (in /usr/bin/python3.10)
==68002==    by 0x41816A6: _PyObject_MakeTpCall (in /usr/bin/python3.10)
==68002==    by 0x417EC93: ??? (in /usr/bin/python3.10)
==68002==    by 0x417E82E: ??? (in /usr/bin/python3.10)
==68002==    by 0x4176B42: _PyEval_EvalFrameDefault (in /usr/bin/python3.10)
==68002==    by 0x4259F55: ??? (in /usr/bin/python3.10)
==68002==    by 0x4259E25: PyEval_EvalCode (in /usr/bin/python3.10)
==68002==    by 0x425F4FC: ??? (in /usr/bin/python3.10)
==68002== 
==68002== 832 bytes in 1 blocks are possibly lost in loss record 202 of 425
==68002==    at 0x4E3880F: malloc (vg_replace_malloc.c:446)
==68002==    by 0x414FEC7: _PyObject_GC_NewVar (in /usr/bin/python3.10)
==68002==    by 0x4174C84: ??? (in /usr/bin/python3.10)
==68002==    by 0x418B63D: _PyFunction_Vectorcall (in /usr/bin/python3.10)
==68002==    by 0x417592E: _PyEval_EvalFrameDefault (in /usr/bin/python3.10)
==68002==    by 0x418B66B: _PyFunction_Vectorcall (in /usr/bin/python3.10)
==68002==    by 0x417592E: _PyEval_EvalFrameDefault (in /usr/bin/python3.10)
==68002==    by 0x418B66B: _PyFunction_Vectorcall (in /usr/bin/python3.10)
==68002==    by 0x417592E: _PyEval_EvalFrameDefault (in /usr/bin/python3.10)
==68002==    by 0x418B66B: _PyFunction_Vectorcall (in /usr/bin/python3.10)
==68002==    by 0x417592E: _PyEval_EvalFrameDefault (in /usr/bin/python3.10)
==68002==    by 0x418B66B: _PyFunction_Vectorcall (in /usr/bin/python3.10)
==68002== 
==68002== 880 (80 direct, 800 indirect) bytes in 1 blocks are definitely lost in loss record 205 of 425
==68002==    at 0x4E3880F: malloc (vg_replace_malloc.c:446)
==68002==    by 0x7D75B0C: create_sim_mat (symnmf.c:245)
==68002==    by 0x7D75C80: create_diag_mat (symnmf.c:297)
==68002==    by 0x7D76F4E: request_standard (symnmfmodule.c:157)
==68002==    by 0x418AE37: ??? (in /usr/bin/python3.10)
==68002==    by 0x418175A: _PyObject_MakeTpCall (in /usr/bin/python3.10)
==68002==    by 0x417B1D5: _PyEval_EvalFrameDefault (in /usr/bin/python3.10)
==68002==    by 0x418B66B: _PyFunction_Vectorcall (in /usr/bin/python3.10)
==68002==    by 0x417592E: _PyEval_EvalFrameDefault (in /usr/bin/python3.10)
==68002==    by 0x418B66B: _PyFunction_Vectorcall (in /usr/bin/python3.10)
==68002==    by 0x417592E: _PyEval_EvalFrameDefault (in /usr/bin/python3.10)
==68002==    by 0x4259F55: ??? (in /usr/bin/python3.10)
==68002== 
==68002== 10,992 bytes in 8 blocks are possibly lost in loss record 402 of 425
==68002==    at 0x4E40408: realloc (vg_replace_malloc.c:1801)
==68002==    by 0x426163C: _PyObject_GC_Resize (in /usr/bin/python3.10)
==68002==    by 0x415F841: _PyTuple_Resize (in /usr/bin/python3.10)
==68002==    by 0x41A8DEC: ??? (in /usr/bin/python3.10)
==68002==    by 0x417592E: _PyEval_EvalFrameDefault (in /usr/bin/python3.10)
==68002==    by 0x4180933: _PyObject_FastCallDictTstate (in /usr/bin/python3.10)
==68002==    by 0x4194B03: ??? (in /usr/bin/python3.10)
==68002==    by 0x41816FB: _PyObject_MakeTpCall (in /usr/bin/python3.10)
==68002==    by 0x417AC46: _PyEval_EvalFrameDefault (in /usr/bin/python3.10)
==68002==    by 0x418B66B: _PyFunction_Vectorcall (in /usr/bin/python3.10)
==68002==    by 0x42AC833: ??? (in /usr/bin/python3.10)
==68002==    by 0x41993CA: PyObject_Call (in /usr/bin/python3.10)
==68002== 
==68002== 41,647 bytes in 20 blocks are possibly lost in loss record 416 of 425
==68002==    at 0x4E3880F: malloc (vg_replace_malloc.c:446)
==68002==    by 0x416DAFE: ??? (in /usr/bin/python3.10)
==68002==    by 0x416BD94: ??? (in /usr/bin/python3.10)
==68002==    by 0x416C620: ??? (in /usr/bin/python3.10)
==68002==    by 0x416C201: ??? (in /usr/bin/python3.10)
==68002==    by 0x416C73A: ??? (in /usr/bin/python3.10)
==68002==    by 0x416C201: ??? (in /usr/bin/python3.10)
==68002==    by 0x425945F: ??? (in /usr/bin/python3.10)
==68002==    by 0x4267F24: ??? (in /usr/bin/python3.10)
==68002==    by 0x418A853: ??? (in /usr/bin/python3.10)
==68002==    by 0x417A8B1: _PyEval_EvalFrameDefault (in /usr/bin/python3.10)
==68002==    by 0x418B66B: _PyFunction_Vectorcall (in /usr/bin/python3.10)
==68002== 
==68002== 137,147 bytes in 74 blocks are possibly lost in loss record 423 of 425
==68002==    at 0x4E3880F: malloc (vg_replace_malloc.c:446)
==68002==    by 0x41B1E67: PyUnicode_Substring (in /usr/bin/python3.10)
==68002==    by 0x4199DC8: ??? (in /usr/bin/python3.10)
==68002==    by 0x4175A73: _PyEval_EvalFrameDefault (in /usr/bin/python3.10)
==68002==    by 0x418B66B: _PyFunction_Vectorcall (in /usr/bin/python3.10)
==68002==    by 0x417592E: _PyEval_EvalFrameDefault (in /usr/bin/python3.10)
==68002==    by 0x4259F55: ??? (in /usr/bin/python3.10)
==68002==    by 0x4259E25: PyEval_EvalCode (in /usr/bin/python3.10)
==68002==    by 0x425F4FC: ??? (in /usr/bin/python3.10)
==68002==    by 0x418B8C8: ??? (in /usr/bin/python3.10)
==68002==    by 0x417B9FB: _PyEval_EvalFrameDefault (in /usr/bin/python3.10)
==68002==    by 0x418B66B: _PyFunction_Vectorcall (in /usr/bin/python3.10)
==68002== 
==68002== LEAK SUMMARY:
==68002==    definitely lost: 80 bytes in 1 blocks
==68002==    indirectly lost: 800 bytes in 10 blocks
==68002==      possibly lost: 194,626 bytes in 110 blocks
==68002==    still reachable: 1,731,671 bytes in 988 blocks
==68002==         suppressed: 46,148 bytes in 1 blocks
==68002== Reachable blocks (those to which a pointer was found) are not shown.
==68002== To see them, rerun with: --leak-check=full --show-leak-kinds=all
==68002== 
==68002== For lists of detected and suppressed errors, rerun with: -s
==68002== ERROR SUMMARY: 12 errors from 12 contexts (suppressed: 0 from 0)
